Workbook

Sheet README
A1: WoW Midnight Season 2 (12.1.5) - action bar planner
A2: Status: all 13 classes and 39 specs are filled in (Hunter, Death Knight, Warrior and Paladin were re-laid under the 2026-10-25 rules).
A4: How to read a spec sheet
A5: Columns A-G (grey = locked): Bar, Slot, Type, Key 1, Key 2, keys reserved for, Importance of slots. They come from input.xlsx except the reserved-for column on slots 52, 53, 54, 57 and 61, which follows the 2026-10-25 rules (52 Mobility, 53/54/57 Defensive, 61 Utility).
A6: Column H keeps the xlsx 'Details' as input notes. The xlsx 'Spell / action' column is kept at the far right for reference only: it did not match your real bars in 33 of 36 spell slots.
A7: Key reach tier (col I) is a live lookup in the 'Key reach tiers' sheet; Priority score (col J) = 2 x reach tier + slot importance; lower = better. Edit the blue tier cells and the scores update.
A8: Column P: on the Beast Mastery sheet it compares to Sylvana's real Myslot bars (KEEP / CHANGE / NEW). On the other Hunter sheets it compares to the Beast Mastery sheet (SAME / DIFFERENT), which is the 'same spell, same slot' rule.
A10: Rules applied
A11: 1. Bars 1-4 use the same keybinds for every spec. Slot, keys, 'keys reserved for' and importance come only from input.xlsx.
A12: 2. Importance 1 is most important. Key reach (how close the key is to your fingers) counts double the bar importance.
A13: 3. SHIFT-R is always Burst; V is always the taunt (pet Growl counts for pet specs). Both stay open if the spec has none.
A14: 4. Bar 1 slots 11-12 and Bar 2 slots 70-72 are shared by every class and spec. Bar 4 is identical for every class and spec.
... A25: UNVERIFIED: Warband Bank Distance Inhibitor use effect; Moonlight Chakram replacing Takedown through /cast Takedown; talent strings with a zero tree hash in game; the AoE priority lists for MM and SV (page text not captured).

Sheet Hunter - Beast Mastery
A1: Bar | B1: Slot | C1: Type | D1: Key 1 | E1: Key 2 | F1: keys reserved for | G1: Importance of slots | H1: Input notes (xlsx Details) | I1: Key reach tier | J1: Priority score | K1: Recommended action | L1: Placed as | M1: ID / macro id | N1: Icon file | O1: Spell rank (1-5) | P1: Change vs Sylvana | Q1: Sylvana's current | R1: Reason | S1: Status | T1: xlsx spell (unreliable) | U1: Icon link
A2: Bar 1 | B2: 1 | C2: Spell | D2: 1 | F2: Attack/Heal | G2: 2 | H2: Beast Cleave | I2: =IFERROR(INDEX('Key reach tiers'!$B$2:$B$48,MATCH(D2,'Key reach tiers'!$A$2:$A$48,0)),3) -> 1 | J2: =IF(G2="","",2*I2+G2) -> 4 | K2: Mend Pet | L2: Spell | M2: 136 | N2: ability_hunter_mendpet | O2: 3 | P2: CHANGE | Q2: Hunter's Mark | R2: Rank 3 pet heal is pressed reactively, so it takes a reach-1 key; Hunter's Mark (rank 2) moves to slot 8. | S2: VERIFIED | T2: Multi-Shot | U2: icon
A3: Bar 1 | B3: 2 | C3: Spell | D3: 2 | F3: Attack/Heal | G3: 1 | I3: =IFERROR(INDEX('Key reach tiers'!$B$2:$B$48,MATCH(D3,'Key reach tiers'!$A$2:$A$48,0)),3) -> 1 | J3: =IF(G3="","",2*I3+G3) -> 3 | K3: Cobra Shot macro 'Cobra' | L3: Macro | M3: 9 | N3: ability_hunter_cobrashot | O3: 5 | P3: KEEP | Q3: macro 9 'Cobra' | R3: Rank 5 filler on a reach-1, importance-1 key; macro also fires pet Claw/Bite/Smack. Keep. | S3: VERIFIED | T3: Kill Command | U3: icon
A4: Bar 1 | B4: 3 | C4: Spell | D4: 3 | F4: Attack/Heal | G4: 1 | I4: =IFERROR(INDEX('Key reach tiers'!$B$2:$B$48,MATCH(D4,'Key reach tiers'!$A$2:$A$48,0)),3) -> 1 | J4: =IF(G4="","",2*I4+G4) -> 3 | K4: Wild Thrash macro 'Wild' | L4: Macro | M4: 33 | N4: ability_hunter_sickem | O4: 4 | P4: KEEP | Q4: macro 33 'Wild' | R4: Rank 4 AoE instant (triggers Beast Cleave) on an importance-1 key. Keep. | S4: VERIFIED | T4: Barbed Shot | U4: icon
A5: Bar 1 | B5: 4 | C5: Spell | D5: 4 | F5: Attack/Heal | G5: 2 | H5: From your BM bar | I5: =IFERROR(INDEX('Key reach tiers'!$B$2:$B$48,MATCH(D5,'Key reach tiers'!$A$2:$A$48,0)),3) -> 1 | J5: =IF(G5="","",2*I5+G5) -> 4 | K5: Bestial Wrath macro 'BW' | L5: Macro | M5: 8 | N5: ability_druid_ferociousbite | O5: 4 | P5: KEEP | Q5: macro 8 'BW' | R5: Wowhead: use Bestial Wrath on cooldown (rank 4), so it also sits on a reach-1 key. Keep. | S5: VERIFIED | T5: Wild Thrash | U5: icon
A6: Bar 1 | B6: 5 | C6: Spell | D6: R | F6: Attack/Heal | G6: 1 | I6: =IFERROR(INDEX('Key reach tiers'!$B$2:$B$48,MATCH(D6,'Key reach tiers'!$A$2:$A$48,0)),3) -> 1 | J6: =IF(G6="","",2*I6+G6) -> 3 | K6: Kill Command macro 'KC' | L6: Macro | M6: 17 | N6: ability_hunter_killcommand | O6: 5 | P6: KEEP | Q6: macro 17 'KC' | R6: Rank 5 on R: reach 1 and importance 1. Keep. | S6: VERIFIED | T6: Cobra Shot | U6: icon
A7: Bar 1 | B7: 6 | C7: Spell | D7: F | F7: Attack/Heal | G7: 2 | H7: AoE opener | I7: =IFERROR(INDEX('Key reach tiers'!$B$2:$B$48,MATCH(D7,'Key reach tiers'!$A$2:$A$48,0)),3) -> 1 | J7: =IF(G7="","",2*I7+G7) -> 4 | K7: Cobra Shot macro 'Cobra' | L7: Macro | M7: 9 | N7: ability_hunter_cobrashot | O7: 5 | P7: KEEP | Q7: macro 9 'Cobra' | R7: Cobra Shot is the most-pressed filler, so a second copy on a reach-1 key is worth it. Keep. | S7: VERIFIED | T7: Dire Beast | U7: icon
A8: Bar 1 | B8: 7 | C8: Spell | D8: BUTTON4 | F8: Attack/Heal | G8: 1 | H8: Dark Ranger | I8: =IFERROR(INDEX('Key reach tiers'!$B$2:$B$48,MATCH(D8,'Key reach tiers'!$A$2:$A$48,0)),3) -> 1 | J8: =IF(G8="","",2*I8+G8) -> 3 | K8: Barbed Shot macro 'Barbed' | L8: Macro | M8: 7 | N8: ability_hunter_barbedshot | O8: 5 | P8: KEEP | Q8: macro 7 'Barbed' | R8: Rank 5 on thumb BUTTON4 (reach 1, importance 1). Keep. | S8: VERIFIED | T8: Black Arrow | U8: icon
A9: Bar 1 | B9: 8 | C9: Spell | D9: SHIFT-BUTTON4 | F9: Attack/Heal | G9: 2 | I9: =IFERROR(INDEX('Key reach tiers'!$B$2:$B$48,MATCH(D9,'Key reach tiers'!$A$2:$A$48,0)),3) -> 2 | J9: =IF(G9="","",2*I9+G9) -> 6 | K9: Hunter's Mark | L9: Spell | M9: 257284 | N9: ability_hunter_markedfordeath | O9: 2 | P9: CHANGE | Q9: Tranquilizing Shot | R9: Rank 2 pre-pull mark; SHIFT-BUTTON4 is thumb-reachable and your xlsx plan also put it here. | S9: VERIFIED | T9: Hunter's Mark | U9: icon
A10: Bar 1 | B10: 9 | C10: Spell | D10: V | F10: Utility | G10: 3 | I10: =IFERROR(INDEX('Key reach tiers'!$B$2:$B$48,MATCH(D10,'Key reach tiers'!$A$2:$A$48,0)),3) -> 2 | J10: =IF(G10="","",2*I10+G10) -> 7 | K10: Growl macro 'Growl' | L10: Macro | M10: 16 | N10: ability_physical_taunt | O10: 3 | P10: KEEP | Q10: macro 16 'Growl' | R10: Rule: V is always the taunt; pet Growl counts for pet specs (your decision). Keep. | S10: VERIFIED | T10: Tranquilizing Shot | U10: icon
A11: Bar 1 | B11: 10 | C11: Spell | D11: SHIFT-V | F11: Utility | G11: 3 | I11: =IFERROR(INDEX('Key reach tiers'!$B$2:$B$48,MATCH(D11,'Key reach tiers'!$A$2:$A$48,0)),3) -> 3 | J11: =IF(G11="","",2*I11+G11) -> 9 | K11: Tame Beast macro 'tame' | L11: Macro | M11: 27 | N11: ability_hunter_beasttaming | O11: 1 | P11: KEEP | Q11: macro 27 'tame' | R11: Rank 1 Tame Beast / Dismiss Pet belongs on a low-reach key (reach 3). Keep. | S11: VERIFIED | T11: Misdirection | U11: icon
A12: Bar 1 | B12: 11 | C12: Item | D12: ALT-MOUSEWHEELUP | F12: Utility | G12: 3 | H12: Unchanged from your BM bar | I12: =IFERROR(INDEX('Key reach tiers'!$B$2:$B$48,MATCH(D12,'Key reach tiers'!$A$2:$A$48,0)),3) -> 3 | J12: =IF(G12="","",2*I12+G12) -> 9 | K12: Interdimensional Companion Repository | L12: Item | M12: 153510 | N12: inv_eng_interdimensionalcompanionrepository | P12: KEEP | Q12: Interdimensional Companion Repository | R12: Shared across every class and spec (confirmed). Keep. | S12: VERIFIED | T12: Item 153510 | U12: icon
A13: Bar 1 | B13: 12 | C13: Item | D13: ALT-MOUSEWHEELDOWN | F13: Utility | G13: 3 | I13: =IFERROR(INDEX('Key reach tiers'!$B$2:$B$48,MATCH(D13,'Key reach tiers'!$A$2:$A$48,0)),3) -> 3 | J13: =IF(G13="","",2*I13+G13) -> 9 | K13: Healthstone | L13: Item | M13: 5512 | N13: warlock_-healthstone | P13: KEEP | Q13: Healthstone | R13: Shared across every class and spec (confirmed). Keep. | S13: VERIFIED | T13: Healthstone | U13: icon
A14: Bar 2 | B14: 61 | C14: Spell | D14: SHIFT-MOUSEWHEELUP | F14: Utility | G14: 3 | I14: =IFERROR(INDEX('Key reach tiers'!$B$2:$B$48,MATCH(D14,'Key reach tiers'!$A$2:$A$48,0)),3) -> 2 | J14: =IF(G14="","",2*I14+G14) -> 7 | K14: Tranquilizing Shot | L14: Spell | M14: 19801 | N14: spell_nature_drowsy | O14: 2 | P14: CHANGE | Q14: macro 29 'TankMDaddon' | R14: Rank 2 enrage/magic dispel on SHIFT-wheel up (reach 2); Misdirection moves to a better slot. | S14: VERIFIED | T14: Flare | U14: icon
A15: Bar 2 | B15: 62 | C15: Spell | D15: C | E15: F9 | F15: Crowd control | G15: 3 | I15: =IFERROR(INDEX('Key reach tiers'!$B$2:$B$48,MATCH(D15,'Key reach tiers'!$A$2:$A$48,0)),3) -> 2 | J15: =IF(G15="","",2*I15+G15) -> 7 | K15: Intimidation macro 'Kick2' | L15: Macro | M15: 18 | N15: ability_devour | O15: 2 | P15: KEEP | Q15: macro 18 'Kick2' | R15: Rank 2 stun/focus-stun macro on C, with F9 as second key. Keep. | S15: VERIFIED | T15: Binding Shot | U15: icon
A16: Bar 2 | B16: 63 | C16: Spell | D16: T | F16: Utility | G16: 3 | I16: =IFERROR(INDEX('Key reach tiers'!$B$2:$B$48,MATCH(D16,'Key reach tiers'!$A$2:$A$48,0)),3) -> 2 | J16: =IF(G16="","",2*I16+G16) -> 7 | K16: Feign Death | L16: Spell | M16: 5384 | N16: ability_rogue_feigndeath | O16: 2 | P16: CHANGE | Q16: macro 32 'Turtle' | R16: Rank 2 panic button on T (reach 2); the Turtle macro moves to a Defensive slot. | S16: VERIFIED | T16: Camouflage | U16: icon
A17: Bar 2 | B17: 64 | C17: Spell | D17: SHIFT-C | F17: Crowd control | G17: 3 | I17: =IFERROR(INDEX('Key reach tiers'!$B$2:$B$48,MATCH(D17,'Key reach tiers'!$A$2:$A$48,0)),3) -> 3 | J17: =IF(G17="","",2*I17+G17) -> 9 | K17: Freezing Trap macro 'Trap' | L17: Macro | M17: 31 | N17: spell_frost_chainsofice | O17: 2 | P17: KEEP | Q17: macro 31 'Trap' | R17: Rank 2 trap dropped at the cursor on SHIFT-C. Keep. | S17: VERIFIED | T17: Freezing Trap | U17: icon
A18: Bar 2 | B18: 65 | C18: Spell | D18: SHIFT-R | F18: Burst | G18: 3 | H18: With racials, trinkets, potion | I18: =IFERROR(INDEX('Key reach tiers'!$B$2:$B$48,MATCH(D18,'Key reach tiers'!$A$2:$A$48,0)),3) -> 2 | J18: =IF(G18="","",2*I18+G18) -> 7 | K18: Bestial Wrath macro 'BW' | L18: Macro | M18: 8 | N18: ability_druid_ferociousbite | O18: 4 | P18: KEEP | Q18: macro 8 'BW' | R18: Rule: SHIFT-R is always burst; the macro bundles racials, trinkets and potion. Keep. | S18: VERIFIED | T18: Bestial Wrath | U18: icon
A19: Bar 2 | B19: 66 | C19: Spell | D19: SHIFT-F | F19: Burst | G19: 3 | I19: =IFERROR(INDEX('Key reach tiers'!$B$2:$B$48,MATCH(D19,'Key reach tiers'!$A$2:$A$48,0)),3) -> 2 | J19: =IF(G19="","",2*I19+G19) -> 7 | K19: (open) | L19: Open | P19: CHANGE | Q19: Feign Death | R19: Pack Leader has no second burst button (Call of the Wild is not in the 12.1.5 BM tree); left open. | S19: UNVERIFIED | T19: Call of the Wild
A20: Bar 2 | B20: 67 | C20: Spell | D20: Z | F20: Burst | G20: 3 | I20: =IFERROR(INDEX('Key reach tiers'!$B$2:$B$48,MATCH(D20,'Key reach tiers'!$A$2:$A$48,0)),3) -> 2 | J20: =IF(G20="","",2*I20+G20) -> 7 | K20: Primal Rage macro 'SX' | L20: Macro | M20: 25 | N20: spell_shadow_unholyfrenzy | O20: 2 | P20: KEEP | Q20: macro 25 'SX' | R20: Rank 2 pet Bloodlust (6 min CD) is the only extra burst. Keep. | S20: VERIFIED | T20: Bloodshed | U20: icon
A21: Bar 2 | B21: 68 | C21: Spell | D21: X | F21: Utility | G21: 3 | I21: =IFERROR(INDEX('Key reach tiers'!$B$2:$B$48,MATCH(D21,'Key reach tiers'!$A$2:$A$48,0)),3) -> 2 | J21: =IF(G21="","",2*I21+G21) -> 7 | K21: Revive Pet | L21: Spell | M21: 982 | N21: ability_hunter_beastsoothe | O21: 2 | P21: CHANGE | Q21: Flare | R21: Rank 2 out-of-combat pet fix; moved to X (tier 2) after you set SHIFT-A to tier 3. | S21: VERIFIED | T21: Tar Trap | U21: icon
A22: Bar 2 | B22: 69 | C22: Spell | F22: Utility | G22: 3 | I22: =IFERROR(INDEX('Key reach tiers'!$B$2:$B$48,MATCH(D22,'Key reach tiers'!$A$2:$A$48,0)),3) -> 3 | J22: =IF(G22="","",2*I22+G22) -> 9 | K22: Beast Lore | L22: Spell | M22: 1462 | N22: ability_physical_taunt | O22: 1 | P22: KEEP | Q22: Beast Lore | R22: Rank 1 on an unbound slot, kept because Bar 4's Beast Lore was removed (class specific). | S22: VERIFIED | T22: Intimidation | U22: icon
A23: Bar 2 | B23: 70 | C23: Item | D23: 6 | F23: Utility | G23: 3 | H23: Unchanged from your BM bar | I23: =IFERROR(INDEX('Key reach tiers'!$B$2:$B$48,MATCH(D23,'Key reach tiers'!$A$2:$A$48,0)),3) -> 2 | J23: =IF(G23="","",2*I23+G23) -> 7 | K23: Voracious Heart of Ula'tek (trinket) | L23: Item | M23: 270175 | N23: inv_121_trinket_raid_ulatek_heart | P23: KEEP | Q23: Voracious Heart of Ula'tek | R23: Shared across every class and spec (confirmed); it is a trinket, so check usability per spec. | S23: VERIFIED | T23: Item 270175 | U23: icon
A24: Bar 2 | B24: 71 | C24: Macro | D24: F10 | F24: Utility | G24: 2 | H24: Your pReck macro (Potion of Recklessness for DPS; use a role-appropriate potion on tank/healer) | I24: =IFERROR(INDEX('Key reach tiers'!$B$2:$B$48,MATCH(D24,'Key reach tiers'!$A$2:$A$48,0)),3) -> 1 | J24: =IF(G24="","",2*I24+G24) -> 4 | K24: Potion macro 'pReck' | L24: Macro | M24: 21 | N24: inv_misc_questionmark | P24: KEEP | Q24: macro 21 'pReck' | R24: Shared; Potion of Recklessness for DPS (role-appropriate potion for tank/healer). Keep. | S24: VERIFIED | T24: Combat potion
A25: Bar 2 | B25: 72 | C25: Macro | D25: F11 | F25: Utility | G25: 2 | H25: Your pHealth macro | I25: =IFERROR(INDEX('Key reach tiers'!$B$2:$B$48,MATCH(D25,'Key reach tiers'!$A$2:$A$48,0)),3) -> 1 | J25: =IF(G25="","",2*I25+G25) -> 4 | K25: Potion macro 'pHealth' | L25: Macro | M25: 19 | N25: inv_misc_questionmark | P25: KEEP | Q25: macro 19 'pHealth' | R25: Shared; health potion then Healthstone. Keep. | S25: VERIFIED | T25: Health potion, then Healthstone
A26: Bar 3 | B26: 49 | C26: Spell | D26: MOUSEWHEELUP | F26: Mobility | G26: 2 | I26: =IFERROR(INDEX('Key reach tiers'!$B$2:$B$48,MATCH(D26,'Key reach tiers'!$A$2:$A$48,0)),3) -> 1 | J26: =IF(G26="","",2*I26+G26) -> 4 | K26: Aspect of the Cheetah | L26: Spell | M26: 186257 | N26: ability_mount_jungletiger | O26: 3 | P26: KEEP | Q26: Aspect of the Cheetah | R26: The only Mobility slot; rank 3. Keep. | S26: VERIFIED | T26: Aspect of the Cheetah | U26: icon
A27: Bar 3 | B27: 50 | C27: Spell | D27: BUTTON5 | F27: Crowd control | G27: 2 | H27: Interrupt | I27: =IFERROR(INDEX('Key reach tiers'!$B$2:$B$48,MATCH(D27,'Key reach tiers'!$A$2:$A$48,0)),3) -> 1 | J27: =IF(G27="","",2*I27+G27) -> 4 | K27: Counter Shot | L27: Spell | M27: 147362 | N27: inv_ammo_arrow_03 | O27: 3 | P27: KEEP | Q27: Counter Shot | R27: Rank 3 interrupt on BUTTON5 (reach 1). Keep. | S27: VERIFIED | T27: Counter Shot | U27: icon
A28: Bar 3 | B28: 51 | C28: Macro (new) | D28: SHIFT-BUTTON5 | F28: Crowd control | G28: 2 | H28: #showtooltip Counter Shot / cast [@focus,exists,harm,nodead] Counter Shot | I28: =IFERROR(INDEX('Key reach tiers'!$B$2:$B$48,MATCH(D28,'Key reach tiers'!$A$2:$A$48,0)),3) -> 2 | J28: =IF(G28="","",2*I28+G28) -> 6 | K28: Counter Shot macro 'CSFocus' | L28: Macro | M28: 10 | N28: inv_ammo_arrow_03 | O28: 3 | P28: KEEP | Q28: macro 10 'CSFocus' | R28: Focus-target interrupt on SHIFT-BUTTON5. Keep. | S28: VERIFIED | T28: Counter Shot on focus | U28: icon
A29: Bar 3 | B29: 52 | C29: Spell | D29: MOUSEWHEELDOWN | F29: Mobility | G29: 2 | I29: =IFERROR(INDEX('Key reach tiers'!$B$2:$B$48,MATCH(D29,'Key reach tiers'!$A$2:$A$48,0)),3) -> 1 | J29: =IF(G29="","",2*I29+G29) -> 4 | K29: Disengage | L29: Spell | M29: 781 | N29: ability_rogue_feint | O29: 3 | P29: KEEP | Q29: Disengage | R29: Rank 3 escape on SHIFT-wheel down (reach 2); exception: Mobility spell in a Utility slot, as in your xlsx plan. | S29: VERIFIED | T29: Aspect of the Turtle | U29: icon
A30: Bar 3 | B30: 53 | C30: Spell | D30: A | F30: Defensive | G30: 2 | I30: =IFERROR(INDEX('Key reach tiers'!$B$2:$B$48,MATCH(D30,'Key reach tiers'!$A$2:$A$48,0)),3) -> 1 | J30: =IF(G30="","",2*I30+G30) -> 4 | K30: Survival of the Fittest | L30: Spell | M30: 264735 | N30: spell_nature_spiritarmor | O30: 2 | P30: CHANGE | Q30: macro 2 'Shadow' | R30: Defensive slot on A; rank 2. Replaces the Shadowmeld macro, which is race-specific and not portable. | S30: VERIFIED | T30: Exhilaration | U30: icon
A31: Bar 3 | B31: 54 | C31: Spell | D31: D | F31: Defensive | G31: 2 | I31: =IFERROR(INDEX('Key reach tiers'!$B$2:$B$48,MATCH(D31,'Key reach tiers'!$A$2:$A$48,0)),3) -> 1 | J31: =IF(G31="","",2*I31+G31) -> 4 | K31: Exhilaration | L31: Spell | M31: 109304 | N31: ability_hunter_onewithnature | O31: 2 | P31: KEEP | Q31: Exhilaration | R31: Rank 2 self-heal on D. Keep. | S31: VERIFIED | T31: Survival of the Fittest | U31: icon
A32: Bar 3 | B32: 55 | C32: Spell | D32: SHIFT-A | F32: Utility | G32: 3 | I32: =IFERROR(INDEX('Key reach tiers'!$B$2:$B$48,MATCH(D32,'Key reach tiers'!$A$2:$A$48,0)),3) -> 3 | J32: =IF(G32="","",2*I32+G32) -> 9 | K32: Flare | L32: Spell | M32: 1543 | N32: spell_fire_flare | O32: 1 | P32: CHANGE | Q32: Revive Pet | R32: Rank 1 situational utility; SHIFT-A is now tier 3 (your edit), so the least-used spell goes here. | S32: VERIFIED | T32: Mend Pet | U32: icon
A33: Bar 3 | B33: 56 | C33: Spell | D33: SHIFT-D | F33: Utility | G33: 2 | I33: =IFERROR(INDEX('Key reach tiers'!$B$2:$B$48,MATCH(D33,'Key reach tiers'!$A$2:$A$48,0)),3) -> 2 | J33: =IF(G33="","",2*I33+G33) -> 6 | K33: Misdirection macro 'TankMDaddon' | L33: Macro | M33: 29 | N33: ability_hunter_misdirection | O33: 3 | P33: CHANGE | Q33: Mend Pet | R33: Rank 3 pull utility on SHIFT-D (reach 2); needs the TankMD addon button. Moved from slot 61. | S33: VERIFIED | T33: Feign Death | U33: icon
A34: Bar 3 | B34: 57 | C34: Spell | D34: SHIFT-MOUSEWHEELDOWN | F34: Defensive | G34: 2 | I34: =IFERROR(INDEX('Key reach tiers'!$B$2:$B$48,MATCH(D34,'Key reach tiers'!$A$2:$A$48,0)),3) -> 2 | J34: =IF(G34="","",2*I34+G34) -> 6 | K34: Aspect of the Turtle macro 'Turtle' | L34: Macro | M34: 32 | N34: ability_hunter_pet_turtle | O34: 2 | P34: CHANGE | Q34: Survival of the Fittest | R34: Defensive slot on wheel down; rank 2. The Turtle macro moves here from T (a Utility slot). | S34: VERIFIED | T34: Disengage | U34: icon
A35: Bar 3 | B35: 58 | C35: Spell | F35: Utility | G35: 3 | I35: =IFERROR(INDEX('Key reach tiers'!$B$2:$B$48,MATCH(D35,'Key reach tiers'!$A$2:$A$48,0)),3) -> 3 | J35: =IF(G35="","",2*I35+G35) -> 9 | K35: Call Pet flyout (flyout 9) | L35: Flyout | M35: 9 | N35: ability_hunter_beastcall | P35: KEEP | Q35: FLYOUT 9 | R35: Pet flyout on an unbound slot, click-only. Keep. | S35: VERIFIED | T35: Primal Rage | U35: icon
A36: Bar 3 | B36: 59 | C36: Macro (new) | D36: SHIFT-F10 | F36: Utility | G36: 3 | H36: #showtooltip Counter Shot / cleartarget / targetenemy / cast Counter Shot / targetlasttarget | I36: =IFERROR(INDEX('Key reach tiers'!$B$2:$B$48,MATCH(D36,'Key reach tiers'!$A$2:$A$48,0)),3) -> 2 | J36: =IF(G36="","",2*I36+G36) -> 7 | K36: Counter Shot macro 'AutoKick' | L36: Macro | M36: 5 | N36: inv_ammo_arrow_03 | O36: 3 | P36: KEEP | Q36: macro 5 'AutoKick' | R36: Interrupt macro on SHIFT-F10; exception: interrupt in a Utility slot, matching your xlsx plan. Keep. | S36: VERIFIED | T36: Counter Shot on tab target | U36: icon
A37: Bar 3 | B37: 60 | C37: Spell | D37: SHIFT-F11 | F37: Utility | G37: 3 | I37: =IFERROR(INDEX('Key reach tiers'!$B$2:$B$48,MATCH(D37,'Key reach tiers'!$A$2:$A$48,0)),3) -> 2 | J37: =IF(G37="","",2*I37+G37) -> 7 | K37: Intimidation macro 'AutoKick2' | L37: Macro | M37: 6 | N37: ability_devour | O37: 2 | P37: KEEP | Q37: macro 6 'AutoKick2' | R37: Focus stun/kick macro on SHIFT-F11; exception: CC in a Utility slot. Keep. | S37: VERIFIED | T37: Revive Pet | U37: icon
A38: Bar 4 | B38: 25 | C38: Item | D38: ALT-0 | F38: Cross char utility | H38: Name not resolved | I38: =IFERROR(INDEX('Key reach tiers'!$B$2:$B$48,MATCH(D38,'Key reach tiers'!$A$2:$A$48,0)),3) -> 3 | J38: =IF(G38="","",2*I38+G38) | K38: Corewarden's Hearthstone | L38: Item | M38: 265100 | N38: inv_cosmicvoid_groundsate | P38: KEEP | Q38: item 265100 | R38: Bar 4 is fixed for all classes and specs. Keep. | S38: VERIFIED | T38: Item 265100 | U38: icon
A39: Bar 4 | B39: 26 | C39: Item | D39: ALT-1 | F39: Cross char utility | H39: Item 140192 | I39: =IFERROR(INDEX('Key reach tiers'!$B$2:$B$48,MATCH(D39,'Key reach tiers'!$A$2:$A$48,0)),3) -> 3 | J39: =IF(G39="","",2*I39+G39) | K39: Dalaran Hearthstone | L39: Item | M39: 140192 | N39: inv_misc_rune_15 | P39: KEEP | Q39: item 140192 | R39: Bar 4 is fixed for all classes and specs. Keep. | S39: VERIFIED | T39: Dalaran Hearthstone | U39: icon
A40: Bar 4 | B40: 27 | C40: Item | D40: ALT-2 | F40: Cross char utility | H40: Name not resolved | I40: =IFERROR(INDEX('Key reach tiers'!$B$2:$B$48,MATCH(D40,'Key reach tiers'!$A$2:$A$48,0)),3) -> 3 | J40: =IF(G40="","",2*I40+G40) | K40: Personal Key to the Arcantina | L40: Item | M40: 253629 | N40: inv_12_-arcantina_key | P40: KEEP | Q40: item 253629 | R40: Bar 4 is fixed for all classes and specs. Keep. | S40: VERIFIED | T40: Item 253629 | U40: icon
...

Sheet Hunter BM spells
A1: Rank (5 = most used) | B1: Spell | C1: Spell ID | D1: Category | E1: Tree | F1: Status | G1: Placed in slot(s) | H1: Note | I1: Icon file | J1: Wowhead link
A2: 5 | B2: Barbed Shot | C2: 217200 | D2: Attack/Heal | E2: spec | F2: VERIFIED | G2: 7 | H2: 2 charges; use before Bestial Wrath | I2: ability_hunter_barbedshot | J2: https://www.wowhead.com/spell=217200
A3: 5 | B3: Cobra Shot | C3: 193455 | D3: Attack/Heal | E3: spec | F3: VERIFIED | G3: 2, 6 | H3: 35 Focus filler | I3: ability_hunter_cobrashot | J3: https://www.wowhead.com/spell=193455
A4: 5 | B4: Kill Command | C4: 34026 | D4: Attack/Heal | E4: spec | F4: VERIFIED | G4: 5 | H4: 30 Focus, 5s CD; cast on Howl of the Pack Leader / Nature's Ally | I4: ability_hunter_killcommand | J4: https://www.wowhead.com/spell=34026
A5: 4 | B5: Bestial Wrath | C5: 19574 | D5: Burst | E5: spec | F5: VERIFIED | G5: 4, 65 | H5: Burst key SHIFT-R; Wowhead says use on cooldown | I5: ability_druid_ferociousbite | J5: https://www.wowhead.com/spell=19574
A6: 4 | B6: Black Arrow | C6: 466930 | D6: Attack/Heal | E6: hero:Dark Ranger | F6: VERIFIED | G6: not placed | H6: Dark Ranger only | I6: inv_ability_darkrangerhunter_blackarrow | J6: https://www.wowhead.com/spell=466930
A7: 4 | B7: Wild Thrash | C7: 1264359 | D7: Attack/Heal | E7: spec | F7: VERIFIED | G7: 3 | H7: AoE instant, triggers Beast Cleave | I7: ability_hunter_sickem | J7: https://www.wowhead.com/spell=1264359
A8: 3 | B8: Aspect of the Cheetah | C8: 186257 | D8: Mobility | E8: baseline | F8: VERIFIED | G8: 49 | I8: ability_mount_jungletiger | J8: https://www.wowhead.com/spell=186257
A9: 3 | B9: Counter Shot | C9: 147362 | D9: Crowd control | E9: class | F9: VERIFIED | G9: 50, 51, 59 | H9: Interrupt, 24s CD | I9: inv_ammo_arrow_03 | J9: https://www.wowhead.com/spell=147362
A10: 3 | B10: Disengage | C10: 781 | D10: Mobility | E10: baseline | F10: VERIFIED | G10: 52 | I10: ability_rogue_feint | J10: https://www.wowhead.com/spell=781
A11: 3 | B11: Growl | C11: 2649 | D11: Utility | E11: pet | F11: VERIFIED | G11: 9 | H11: Pet taunt. Counts as the V taunt for pet specs (user decision) | I11: ability_physical_taunt | J11: https://www.wowhead.com/spell=2649
A12: 3 | B12: Mend Pet | C12: 136 | D12: Attack/Heal | E12: baseline | F12: VERIFIED | G12: 1 | H12: Pet heal, used often | I12: ability_hunter_mendpet | J12: https://www.wowhead.com/spell=136
A13: 3 | B13: Misdirection | C13: 34477 | D13: Utility | E13: class | F13: VERIFIED | G13: 56 | H13: Sylvana uses TankMDaddon macro | I13: ability_hunter_misdirection | J13: https://www.wowhead.com/spell=34477
A14: 3 | B14: Wailing Arrow | C14: 355589 | D14: Attack/Heal | E14: hero:Dark Ranger | F14: VERIFIED | G14: not placed | H14: Dark Ranger only; 1 min CD, AoE silence. Three spell ids exist (354831/355589/355596); 355589 is the cast with Focus cost | I14: ability_theblackarrow | J14: https://www.wowhead.com/spell=355589
A15: 2 | B15: Aspect of the Turtle | C15: 186265 | D15: Defensive | E15: baseline | F15: VERIFIED | G15: 57 | I15: ability_hunter_pet_turtle | J15: https://www.wowhead.com/spell=186265
A16: 2 | B16: Binding Shot | C16: 109248 | D16: Crowd control | E16: class | F16: VERIFIED | G16: not placed | I16: spell_shaman_bindelemental | J16: https://www.wowhead.com/spell=109248
A17: 2 | B17: Exhilaration | C17: 109304 | D17: Defensive | E17: baseline | F17: VERIFIED | G17: 54 | I17: ability_hunter_onewithnature | J17: https://www.wowhead.com/spell=109304
A18: 2 | B18: Feign Death | C18: 5384 | D18: Utility | E18: baseline | F18: VERIFIED | G18: 63 | I18: ability_rogue_feigndeath | J18: https://www.wowhead.com/spell=5384
A19: 2 | B19: Freezing Trap | C19: 187650 | D19: Crowd control | E19: baseline | F19: VERIFIED | G19: 64 | H19: Macro 'Trap' casts at cursor | I19: spell_frost_chainsofice | J19: https://www.wowhead.com/spell=187650
A20: 2 | B20: Hunter's Mark | C20: 257284 | D20: Attack/Heal | E20: baseline | F20: VERIFIED | G20: 8 | H20: Sylvana: slot 1, key 1 | I20: ability_hunter_markedfordeath | J20: https://www.wowhead.com/spell=257284
A21: 2 | B21: Intimidation | C21: 19577 | D21: Crowd control | E21: class | F21: VERIFIED | G21: 60, 62 | H21: Stun, 1 min CD | I21: ability_devour | J21: https://www.wowhead.com/spell=19577
A22: 2 | B22: Multi-Shot | C22: 2643 | D22: Attack/Heal | E22: baseline | F22: UNVERIFIED | G22: not placed | H22: Not in the BM talent tree; present in Sylvana's macro 'MS'. Confirm it is castable on BM in 12.1.5 | I22: ability_upgrademoonglaive | J22: https://www.wowhead.com/spell=2643
A23: 2 | B23: Primal Rage | C23: 264667 | D23: Burst | E23: pet | F23: VERIFIED | G23: 67 | H23: 6 min CD pet Bloodlust, cast via [pet] macro | I23: spell_shadow_unholyfrenzy | J23: https://www.wowhead.com/spell=264667
A24: 2 | B24: Revive Pet | C24: 982 | D24: Utility | E24: baseline | F24: VERIFIED | G24: 68 | I24: ability_hunter_beastsoothe | J24: https://www.wowhead.com/spell=982
A25: 2 | B25: Survival of the Fittest | C25: 264735 | D25: Defensive | E25: class | F25: VERIFIED | G25: 53 | I25: spell_nature_spiritarmor | J25: https://www.wowhead.com/spell=264735
A26: 2 | B26: Tranquilizing Shot | C26: 19801 | D26: Utility | E26: class | F26: VERIFIED | G26: 61 | H26: Dispel enrage/magic | I26: spell_nature_drowsy | J26: https://www.wowhead.com/spell=19801
A27: 1 | B27: Arcane Shot | C27: 185358 | D27: Attack/Heal | E27: baseline | F27: UNVERIFIED | G27: not placed | H27: Not in BM priority; Sylvana has macro 'ArS' | I27: ability_impalingbolt | J27: https://www.wowhead.com/spell=185358
A28: 1 | B28: Beast Lore | C28: 1462 | D28: Utility | E28: baseline | F28: VERIFIED | G28: 69 | H28: Removed from Bar 4 (class specific) | I28: ability_physical_taunt | J28: https://www.wowhead.com/spell=1462
A29: 1 | B29: Call Pet 1 | C29: 883 | D29: Utility | E29: baseline | F29: VERIFIED | G29: not placed | I29: ability_hunter_beastcall | J29: https://www.wowhead.com/spell=883
A30: 1 | B30: Call of the Wild | C30: 359844 | D30: Burst | E30: unknown | F30: UNVERIFIED | G30: not placed | H30: Spell exists in DB but is not in the 12.1.5 BM talent tree | I30: ability_hunter_callofthewild | J30: https://www.wowhead.com/spell=359844
A31: 1 | B31: Camouflage | C31: 199483 | D31: Utility | E31: class | F31: VERIFIED | G31: not placed | I31: ability_hunter_camouflage | J31: https://www.wowhead.com/spell=199483
A32: 1 | B32: Concussive Shot | C32: 5116 | D32: Crowd control | E32: class | F32: VERIFIED | G32: not placed | I32: spell_frost_stun | J32: https://www.wowhead.com/spell=5116
A33: 1 | B33: Dismiss Pet | C33: 2641 | D33: Utility | E33: baseline | F33: VERIFIED | G33: not placed | I33: spell_nature_spiritwolf | J33: https://www.wowhead.com/spell=2641
A34: 1 | B34: Flare | C34: 1543 | D34: Utility | E34: baseline | F34: VERIFIED | G34: 55 | H34: Cursor macro FlareCursor | I34: spell_fire_flare | J34: https://www.wowhead.com/spell=1543
A35: 1 | B35: Implosive Trap | C35: 462031 | D35: Crowd control | E35: unknown | F35: UNVERIFIED | G35: not placed | H35: In Sylvana's macro 'IT' but not in the tree dump | I35: 6bf_explosive_shard | J35: https://www.wowhead.com/spell=462031
A36: 1 | B36: Kill Shot | C36: 53351 | D36: Attack/Heal | E36: talent (other spec?) | F36: UNVERIFIED | G36: not placed | H36: Not in the BM tree dump | I36: ability_hunter_assassinate2 | J36: https://www.wowhead.com/spell=53351
A37: 1 | B37: Roar of Sacrifice | C37: 53480 | D37: Defensive | E37: class choice | F37: VERIFIED | G37: not placed | H37: Choice node with Guardian's Hide | I37: ability_hunter_fervor | J37: https://www.wowhead.com/spell=53480
A38: 1 | B38: Scare Beast | C38: 1513 | D38: Crowd control | E38: class choice | F38: VERIFIED | G38: not placed | H38: Choice node with Tar Trap | I38: ability_druid_cower | J38: https://www.wowhead.com/spell=1513
A39: 1 | B39: Steady Shot | C39: 56641 | D39: Attack/Heal | E39: baseline | F39: VERIFIED | G39: not placed | H39: In Sylvana's hidden bar slot 127 | I39: ability_hunter_steadyshot | J39: https://www.wowhead.com/spell=56641
A40: 1 | B40: Tame Beast | C40: 1515 | D40: Utility | E40: baseline | F40: VERIFIED | G40: 10 | H40: Sylvana has tame macros | I40: ability_hunter_beasttaming | J40: https://www.wowhead.com/spell=1515
...

Sheet Hunter - Marksmanship
A1: Bar | B1: Slot | C1: Type | D1: Key 1 | E1: Key 2 | F1: keys reserved for | G1: Importance of slots | H1: Input notes (xlsx Details) | I1: Key reach tier | J1: Priority score | K1: Recommended action | L1: Placed as | M1: ID / macro id | N1: Icon file | O1: Spell rank (1-5) | P1: vs Beast Mastery | Q1: Beast Mastery has | R1: Reason | S1: Status | T1: xlsx spell (unreliable) | U1: Icon link
A2: Bar 1 | B2: 1 | C2: Spell | D2: 1 | F2: Attack/Heal | G2: 2 | H2: Beast Cleave | I2: =IFERROR(INDEX('Key reach tiers'!$B$2:$B$48,MATCH(D2,'Key reach tiers'!$A$2:$A$48,0)),3) -> 1 | J2: =IF(G2="","",2*I2+G2) -> 4 | K2: Mend Pet | L2: Spell | M2: 136 | N2: ability_hunter_mendpet | O2: 2 | P2: SAME | Q2: Mend Pet | R2: Same as Beast Mastery. | S2: VERIFIED | T2: Multi-Shot | U2: icon
A3: Bar 1 | B3: 2 | C3: Spell | D3: 2 | F3: Attack/Heal | G3: 1 | I3: =IFERROR(INDEX('Key reach tiers'!$B$2:$B$48,MATCH(D3,'Key reach tiers'!$A$2:$A$48,0)),3) -> 1 | J3: =IF(G3="","",2*I3+G3) -> 3 | K3: Rapid Fire | L3: Spell | M3: 257044 | N3: ability_hunter_efficiency | O3: 5 | P3: DIFFERENT | Q3: Cobra Shot macro 'Cobra' | R3: Rank 5, on cooldown; R is reach 1 and importance 1. | S3: VERIFIED | T3: Kill Command | U3: icon
A4: Bar 1 | B4: 3 | C4: Spell | D4: 3 | F4: Attack/Heal | G4: 1 | I4: =IFERROR(INDEX('Key reach tiers'!$B$2:$B$48,MATCH(D4,'Key reach tiers'!$A$2:$A$48,0)),3) -> 1 | J4: =IF(G4="","",2*I4+G4) -> 3 | K4: Multi-Shot macro 'MS' | L4: Macro | M4: 133 | N4: ability_upgrademoonglaive | O4: 4 | P4: DIFFERENT | Q4: Wild Thrash macro 'Wild' | R4: Same job as Wild Thrash in BM: the AoE button on key 3. Macro sends the pet in first. | S4: VERIFIED | T4: Barbed Shot | U4: icon
A5: Bar 1 | B5: 4 | C5: Spell | D5: 4 | F5: Attack/Heal | G5: 2 | H5: From your BM bar | I5: =IFERROR(INDEX('Key reach tiers'!$B$2:$B$48,MATCH(D5,'Key reach tiers'!$A$2:$A$48,0)),3) -> 1 | J5: =IF(G5="","",2*I5+G5) -> 4 | K5: Explosive Shot | L5: Spell | M5: 212431 | N5: ability_hunter_explosiveshot | O5: 4 | P5: DIFFERENT | Q5: Bestial Wrath macro 'BW' | R5: Rank 4, on cooldown. Takes the slot BM uses for its cooldown button (Bestial Wrath). | S5: VERIFIED | T5: Wild Thrash | U5: icon
A6: Bar 1 | B6: 5 | C6: Spell | D6: R | F6: Attack/Heal | G6: 1 | I6: =IFERROR(INDEX('Key reach tiers'!$B$2:$B$48,MATCH(D6,'Key reach tiers'!$A$2:$A$48,0)),3) -> 1 | J6: =IF(G6="","",2*I6+G6) -> 3 | K6: Aimed Shot macro 'AS' | L6: Macro | M6: 124 | N6: 8026692 | O6: 5 | P6: DIFFERENT | Q6: Kill Command macro 'KC' | R6: Rank 5, cast on cooldown; first attack slot on an importance-1 key (BM has its main filler here). Macro keeps Aimed Shot from cancelling Rapid Fire. | S6: VERIFIED | T6: Cobra Shot | U6: icon
A7: Bar 1 | B7: 6 | C7: Spell | D7: F | F7: Attack/Heal | G7: 2 | H7: AoE opener | I7: =IFERROR(INDEX('Key reach tiers'!$B$2:$B$48,MATCH(D7,'Key reach tiers'!$A$2:$A$48,0)),3) -> 1 | J7: =IF(G7="","",2*I7+G7) -> 4 | K7: Steady Shot | L7: Spell | M7: 56641 | N7: ability_hunter_steadyshot | O7: 4 | P7: DIFFERENT | Q7: Cobra Shot macro 'Cobra' | R7: Filler on F, like Cobra Shot in BM (rank 4, castable on the move). | S7: VERIFIED | T7: Dire Beast | U7: icon
A8: Bar 1 | B8: 7 | C8: Spell | D8: BUTTON4 | F8: Attack/Heal | G8: 1 | H8: Dark Ranger | I8: =IFERROR(INDEX('Key reach tiers'!$B$2:$B$48,MATCH(D8,'Key reach tiers'!$A$2:$A$48,0)),3) -> 1 | J8: =IF(G8="","",2*I8+G8) -> 3 | K8: Arcane Shot macro 'ArS' | L8: Macro | M8: 123 | N8: ability_impalingbolt | O8: 5 | P8: DIFFERENT | Q8: Barbed Shot macro 'Barbed' | R8: Rank 5 Precise Shots spender on the thumb button; macro avoids cancelling Rapid Fire. | S8: VERIFIED | T8: Black Arrow | U8: icon
A9: Bar 1 | B9: 8 | C9: Spell | D9: SHIFT-BUTTON4 | F9: Attack/Heal | G9: 2 | I9: =IFERROR(INDEX('Key reach tiers'!$B$2:$B$48,MATCH(D9,'Key reach tiers'!$A$2:$A$48,0)),3) -> 2 | J9: =IF(G9="","",2*I9+G9) -> 6 | K9: Hunter's Mark | L9: Spell | M9: 257284 | N9: ability_hunter_markedfordeath | O9: 2 | P9: SAME | Q9: Hunter's Mark | R9: Same as Beast Mastery. | S9: VERIFIED | T9: Hunter's Mark | U9: icon
A10: Bar 1 | B10: 9 | C10: Spell | D10: V | F10: Utility | G10: 3 | I10: =IFERROR(INDEX('Key reach tiers'!$B$2:$B$48,MATCH(D10,'Key reach tiers'!$A$2:$A$48,0)),3) -> 2 | J10: =IF(G10="","",2*I10+G10) -> 7 | K10: Growl macro 'Growl' | L10: Macro | M10: 16 | N10: ability_physical_taunt | O10: 2 | P10: SAME | Q10: Growl macro 'Growl' | R10: Same as Beast Mastery. | S10: VERIFIED | T10: Tranquilizing Shot | U10: icon
A11: Bar 1 | B11: 10 | C11: Spell | D11: SHIFT-V | F11: Utility | G11: 3 | I11: =IFERROR(INDEX('Key reach tiers'!$B$2:$B$48,MATCH(D11,'Key reach tiers'!$A$2:$A$48,0)),3) -> 3 | J11: =IF(G11="","",2*I11+G11) -> 9 | K11: Tame Beast macro 'tame' | L11: Macro | M11: 27 | N11: ability_hunter_beasttaming | O11: 1 | P11: SAME | Q11: Tame Beast macro 'tame' | R11: Same as Beast Mastery. | S11: VERIFIED | T11: Misdirection | U11: icon
A12: Bar 1 | B12: 11 | C12: Item | D12: ALT-MOUSEWHEELUP | F12: Utility | G12: 3 | H12: Unchanged from your BM bar | I12: =IFERROR(INDEX('Key reach tiers'!$B$2:$B$48,MATCH(D12,'Key reach tiers'!$A$2:$A$48,0)),3) -> 3 | J12: =IF(G12="","",2*I12+G12) -> 9 | K12: Interdimensional Companion Repository | L12: Item | M12: 153510 | N12: inv_eng_interdimensionalcompanionrepository | P12: SAME | Q12: Interdimensional Companion Repository | R12: Same as Beast Mastery. | S12: VERIFIED | T12: Item 153510 | U12: icon
A13: Bar 1 | B13: 12 | C13: Item | D13: ALT-MOUSEWHEELDOWN | F13: Utility | G13: 3 | I13: =IFERROR(INDEX('Key reach tiers'!$B$2:$B$48,MATCH(D13,'Key reach tiers'!$A$2:$A$48,0)),3) -> 3 | J13: =IF(G13="","",2*I13+G13) -> 9 | K13: Healthstone | L13: Item | M13: 5512 | N13: warlock_-healthstone | P13: SAME | Q13: Healthstone | R13: Same as Beast Mastery. | S13: VERIFIED | T13: Healthstone | U13: icon
A14: Bar 2 | B14: 61 | C14: Spell | D14: SHIFT-MOUSEWHEELUP | F14: Utility | G14: 3 | I14: =IFERROR(INDEX('Key reach tiers'!$B$2:$B$48,MATCH(D14,'Key reach tiers'!$A$2:$A$48,0)),3) -> 2 | J14: =IF(G14="","",2*I14+G14) -> 7 | K14: Tranquilizing Shot | L14: Spell | M14: 19801 | N14: spell_nature_drowsy | O14: 1 | P14: SAME | Q14: Tranquilizing Shot | R14: Same as Beast Mastery. | S14: VERIFIED | T14: Flare | U14: icon
A15: Bar 2 | B15: 62 | C15: Spell | D15: C | E15: F9 | F15: Crowd control | G15: 3 | I15: =IFERROR(INDEX('Key reach tiers'!$B$2:$B$48,MATCH(D15,'Key reach tiers'!$A$2:$A$48,0)),3) -> 2 | J15: =IF(G15="","",2*I15+G15) -> 7 | K15: Intimidation macro 'Kick2' | L15: Macro | M15: 18 | N15: artifactability_survivalhunter_eaglesbite | O15: 2 | P15: SAME | Q15: Intimidation macro 'Kick2' | R15: Same as Beast Mastery. | S15: VERIFIED | T15: Binding Shot | U15: icon
A16: Bar 2 | B16: 63 | C16: Spell | D16: T | F16: Utility | G16: 3 | I16: =IFERROR(INDEX('Key reach tiers'!$B$2:$B$48,MATCH(D16,'Key reach tiers'!$A$2:$A$48,0)),3) -> 2 | J16: =IF(G16="","",2*I16+G16) -> 7 | K16: Feign Death | L16: Spell | M16: 5384 | N16: ability_rogue_feigndeath | O16: 2 | P16: SAME | Q16: Feign Death | R16: Same as Beast Mastery. | S16: VERIFIED | T16: Camouflage | U16: icon
A17: Bar 2 | B17: 64 | C17: Spell | D17: SHIFT-C | F17: Crowd control | G17: 3 | I17: =IFERROR(INDEX('Key reach tiers'!$B$2:$B$48,MATCH(D17,'Key reach tiers'!$A$2:$A$48,0)),3) -> 3 | J17: =IF(G17="","",2*I17+G17) -> 9 | K17: Freezing Trap macro 'Trap' | L17: Macro | M17: 31 | N17: spell_frost_chainsofice | O17: 2 | P17: SAME | Q17: Freezing Trap macro 'Trap' | R17: Same as Beast Mastery. | S17: VERIFIED | T17: Freezing Trap | U17: icon
A18: Bar 2 | B18: 65 | C18: Spell | D18: SHIFT-R | F18: Burst | G18: 3 | H18: With racials, trinkets, potion | I18: =IFERROR(INDEX('Key reach tiers'!$B$2:$B$48,MATCH(D18,'Key reach tiers'!$A$2:$A$48,0)),3) -> 2 | J18: =IF(G18="","",2*I18+G18) -> 7 | K18: Trueshot macro 'TS' | L18: Macro | M18: 34 | N18: ability_trueshot | O18: 4 | P18: DIFFERENT | Q18: Bestial Wrath macro 'BW' | R18: Rule: SHIFT-R is Burst. New macro: Trueshot plus both trinkets, no racials so it works for any race. | S18: VERIFIED | T18: Bestial Wrath | U18: icon
A19: Bar 2 | B19: 66 | C19: Spell | D19: SHIFT-F | F19: Burst | G19: 3 | I19: =IFERROR(INDEX('Key reach tiers'!$B$2:$B$48,MATCH(D19,'Key reach tiers'!$A$2:$A$48,0)),3) -> 2 | J19: =IF(G19="","",2*I19+G19) -> 7 | K19: Volley | L19: Spell | M19: 260243 | N19: ability_hunter_rapidkilling | O19: 4 | P19: DIFFERENT | Q19: (open) | R19: Rank 4 on-cooldown big hit; the only free Burst-reserved key left. BM leaves this slot open. | S19: VERIFIED | T19: Call of the Wild | U19: icon
A20: Bar 2 | B20: 67 | C20: Spell | D20: Z | F20: Burst | G20: 3 | I20: =IFERROR(INDEX('Key reach tiers'!$B$2:$B$48,MATCH(D20,'Key reach tiers'!$A$2:$A$48,0)),3) -> 2 | J20: =IF(G20="","",2*I20+G20) -> 7 | K20: Moonlight Chakram | L20: Spell | M20: 1264902 | N20: inv_ability_hunter_deathchakram | O20: 3 | P20: DIFFERENT | Q20: Primal Rage macro 'SX' | R20: Sentinel hero ability, cast with Trueshot. Replaces Primal Rage, which MM rarely needs. | S20: VERIFIED | T20: Bloodshed | U20: icon
A21: Bar 2 | B21: 68 | C21: Spell | D21: X | F21: Utility | G21: 3 | I21: =IFERROR(INDEX('Key reach tiers'!$B$2:$B$48,MATCH(D21,'Key reach tiers'!$A$2:$A$48,0)),3) -> 2 | J21: =IF(G21="","",2*I21+G21) -> 7 | K21: Revive Pet | L21: Spell | M21: 982 | N21: ability_hunter_beastsoothe | O21: 2 | P21: SAME | Q21: Revive Pet | R21: Same as Beast Mastery. | S21: VERIFIED | T21: Tar Trap | U21: icon
A22: Bar 2 | B22: 69 | C22: Spell | F22: Utility | G22: 3 | I22: =IFERROR(INDEX('Key reach tiers'!$B$2:$B$48,MATCH(D22,'Key reach tiers'!$A$2:$A$48,0)),3) -> 3 | J22: =IF(G22="","",2*I22+G22) -> 9 | K22: Beast Lore | L22: Spell | M22: 1462 | N22: ability_physical_taunt | O22: 1 | P22: SAME | Q22: Beast Lore | R22: Same as Beast Mastery. | S22: VERIFIED | T22: Intimidation | U22: icon
A23: Bar 2 | B23: 70 | C23: Item | D23: 6 | F23: Utility | G23: 3 | H23: Unchanged from your BM bar | I23: =IFERROR(INDEX('Key reach tiers'!$B$2:$B$48,MATCH(D23,'Key reach tiers'!$A$2:$A$48,0)),3) -> 2 | J23: =IF(G23="","",2*I23+G23) -> 7 | K23: Voracious Heart of Ula'tek (trinket) | L23: Item | M23: 270175 | N23: inv_121_trinket_raid_ulatek_heart | P23: SAME | Q23: Voracious Heart of Ula'tek (trinket) | R23: Same as Beast Mastery. | S23: VERIFIED | T23: Item 270175 | U23: icon
A24: Bar 2 | B24: 71 | C24: Macro | D24: F10 | F24: Utility | G24: 2 | H24: Your pReck macro (Potion of Recklessness for DPS; use a role-appropriate potion on tank/healer) | I24: =IFERROR(INDEX('Key reach tiers'!$B$2:$B$48,MATCH(D24,'Key reach tiers'!$A$2:$A$48,0)),3) -> 1 | J24: =IF(G24="","",2*I24+G24) -> 4 | K24: Potion macro 'pReck' | L24: Macro | M24: 21 | N24: inv_misc_questionmark | P24: SAME | Q24: Potion macro 'pReck' | R24: Same as Beast Mastery. | S24: VERIFIED | T24: Combat potion
A25: Bar 2 | B25: 72 | C25: Macro | D25: F11 | F25: Utility | G25: 2 | H25: Your pHealth macro | I25: =IFERROR(INDEX('Key reach tiers'!$B$2:$B$48,MATCH(D25,'Key reach tiers'!$A$2:$A$48,0)),3) -> 1 | J25: =IF(G25="","",2*I25+G25) -> 4 | K25: Potion macro 'pHealth' | L25: Macro | M25: 19 | N25: inv_misc_questionmark | P25: SAME | Q25: Potion macro 'pHealth' | R25: Same as Beast Mastery. | S25: VERIFIED | T25: Health potion, then Healthstone
A26: Bar 3 | B26: 49 | C26: Spell | D26: MOUSEWHEELUP | F26: Mobility | G26: 2 | I26: =IFERROR(INDEX('Key reach tiers'!$B$2:$B$48,MATCH(D26,'Key reach tiers'!$A$2:$A$48,0)),3) -> 1 | J26: =IF(G26="","",2*I26+G26) -> 4 | K26: Aspect of the Cheetah | L26: Spell | M26: 186257 | N26: ability_mount_jungletiger | O26: 3 | P26: SAME | Q26: Aspect of the Cheetah | R26: Same as Beast Mastery. | S26: VERIFIED | T26: Aspect of the Cheetah | U26: icon
A27: Bar 3 | B27: 50 | C27: Spell | D27: BUTTON5 | F27: Crowd control | G27: 2 | H27: Interrupt | I27: =IFERROR(INDEX('Key reach tiers'!$B$2:$B$48,MATCH(D27,'Key reach tiers'!$A$2:$A$48,0)),3) -> 1 | J27: =IF(G27="","",2*I27+G27) -> 4 | K27: Counter Shot | L27: Spell | M27: 147362 | N27: inv_ammo_arrow_03 | O27: 3 | P27: SAME | Q27: Counter Shot | R27: Same as Beast Mastery. | S27: VERIFIED | T27: Counter Shot | U27: icon
A28: Bar 3 | B28: 51 | C28: Macro (new) | D28: SHIFT-BUTTON5 | F28: Crowd control | G28: 2 | H28: #showtooltip Counter Shot / cast [@focus,exists,harm,nodead] Counter Shot | I28: =IFERROR(INDEX('Key reach tiers'!$B$2:$B$48,MATCH(D28,'Key reach tiers'!$A$2:$A$48,0)),3) -> 2 | J28: =IF(G28="","",2*I28+G28) -> 6 | K28: Counter Shot macro 'CSFocus' | L28: Macro | M28: 10 | N28: inv_ammo_arrow_03 | O28: 3 | P28: SAME | Q28: Counter Shot macro 'CSFocus' | R28: Same as Beast Mastery. | S28: VERIFIED | T28: Counter Shot on focus | U28: icon
A29: Bar 3 | B29: 52 | C29: Spell | D29: MOUSEWHEELDOWN | F29: Mobility | G29: 2 | I29: =IFERROR(INDEX('Key reach tiers'!$B$2:$B$48,MATCH(D29,'Key reach tiers'!$A$2:$A$48,0)),3) -> 1 | J29: =IF(G29="","",2*I29+G29) -> 4 | K29: Disengage | L29: Spell | M29: 781 | N29: ability_rogue_feint | O29: 3 | P29: SAME | Q29: Disengage | R29: Same as Beast Mastery. | S29: VERIFIED | T29: Aspect of the Turtle | U29: icon
A30: Bar 3 | B30: 53 | C30: Spell | D30: A | F30: Defensive | G30: 2 | I30: =IFERROR(INDEX('Key reach tiers'!$B$2:$B$48,MATCH(D30,'Key reach tiers'!$A$2:$A$48,0)),3) -> 1 | J30: =IF(G30="","",2*I30+G30) -> 4 | K30: Survival of the Fittest | L30: Spell | M30: 264735 | N30: spell_nature_spiritarmor | O30: 2 | P30: SAME | Q30: Survival of the Fittest | R30: Same as Beast Mastery. | S30: VERIFIED | T30: Exhilaration | U30: icon
A31: Bar 3 | B31: 54 | C31: Spell | D31: D | F31: Defensive | G31: 2 | I31: =IFERROR(INDEX('Key reach tiers'!$B$2:$B$48,MATCH(D31,'Key reach tiers'!$A$2:$A$48,0)),3) -> 1 | J31: =IF(G31="","",2*I31+G31) -> 4 | K31: Exhilaration | L31: Spell | M31: 109304 | N31: ability_hunter_onewithnature | O31: 2 | P31: SAME | Q31: Exhilaration | R31: Same as Beast Mastery. | S31: VERIFIED | T31: Survival of the Fittest | U31: icon
A32: Bar 3 | B32: 55 | C32: Spell | D32: SHIFT-A | F32: Utility | G32: 3 | I32: =IFERROR(INDEX('Key reach tiers'!$B$2:$B$48,MATCH(D32,'Key reach tiers'!$A$2:$A$48,0)),3) -> 3 | J32: =IF(G32="","",2*I32+G32) -> 9 | K32: Kill Shot | L32: Spell | M32: 53351 | N32: ability_hunter_assassinate2 | O32: 3 | P32: DIFFERENT | Q32: Flare | R32: Rank 3 execute spender. Exception: an attack spell in a Utility slot, because slots 1-8 are full; replaces BM's Flare. | S32: VERIFIED | T32: Mend Pet | U32: icon
A33: Bar 3 | B33: 56 | C33: Spell | D33: SHIFT-D | F33: Utility | G33: 2 | I33: =IFERROR(INDEX('Key reach tiers'!$B$2:$B$48,MATCH(D33,'Key reach tiers'!$A$2:$A$48,0)),3) -> 2 | J33: =IF(G33="","",2*I33+G33) -> 6 | K33: Misdirection macro 'TankMDaddon' | L33: Macro | M33: 29 | N33: ability_hunter_misdirection | O33: 3 | P33: SAME | Q33: Misdirection macro 'TankMDaddon' | R33: Same as Beast Mastery. | S33: VERIFIED | T33: Feign Death | U33: icon
A34: Bar 3 | B34: 57 | C34: Spell | D34: SHIFT-MOUSEWHEELDOWN | F34: Defensive | G34: 2 | I34: =IFERROR(INDEX('Key reach tiers'!$B$2:$B$48,MATCH(D34,'Key reach tiers'!$A$2:$A$48,0)),3) -> 2 | J34: =IF(G34="","",2*I34+G34) -> 6 | K34: Aspect of the Turtle macro 'Turtle' | L34: Macro | M34: 32 | N34: ability_hunter_pet_turtle | O34: 2 | P34: SAME | Q34: Aspect of the Turtle macro 'Turtle' | R34: Same as Beast Mastery. | S34: VERIFIED | T34: Disengage | U34: icon
A35: Bar 3 | B35: 58 | C35: Spell | F35: Utility | G35: 3 | I35: =IFERROR(INDEX('Key reach tiers'!$B$2:$B$48,MATCH(D35,'Key reach tiers'!$A$2:$A$48,0)),3) -> 3 | J35: =IF(G35="","",2*I35+G35) -> 9 | K35: Call Pet flyout (flyout 9) | L35: Flyout | M35: 9 | N35: ability_hunter_beastcall | P35: SAME | Q35: Call Pet flyout (flyout 9) | R35: Same as Beast Mastery. | S35: VERIFIED | T35: Primal Rage | U35: icon
A36: Bar 3 | B36: 59 | C36: Macro (new) | D36: SHIFT-F10 | F36: Utility | G36: 3 | H36: #showtooltip Counter Shot / cleartarget / targetenemy / cast Counter Shot / targetlasttarget | I36: =IFERROR(INDEX('Key reach tiers'!$B$2:$B$48,MATCH(D36,'Key reach tiers'!$A$2:$A$48,0)),3) -> 2 | J36: =IF(G36="","",2*I36+G36) -> 7 | K36: Counter Shot macro 'AutoKick' | L36: Macro | M36: 5 | N36: inv_ammo_arrow_03 | O36: 3 | P36: SAME | Q36: Counter Shot macro 'AutoKick' | R36: Same as Beast Mastery. | S36: VERIFIED | T36: Counter Shot on tab target | U36: icon
A37: Bar 3 | B37: 60 | C37: Spell | D37: SHIFT-F11 | F37: Utility | G37: 3 | I37: =IFERROR(INDEX('Key reach tiers'!$B$2:$B$48,MATCH(D37,'Key reach tiers'!$A$2:$A$48,0)),3) -> 2 | J37: =IF(G37="","",2*I37+G37) -> 7 | K37: Intimidation macro 'AutoKick2' | L37: Macro | M37: 6 | N37: artifactability_survivalhunter_eaglesbite | O37: 2 | P37: SAME | Q37: Intimidation macro 'AutoKick2' | R37: Same as Beast Mastery. | S37: VERIFIED | T37: Revive Pet | U37: icon
A38: Bar 4 | B38: 25 | C38: Item | D38: ALT-0 | F38: Cross char utility | H38: Name not resolved | I38: =IFERROR(INDEX('Key reach tiers'!$B$2:$B$48,MATCH(D38,'Key reach tiers'!$A$2:$A$48,0)),3) -> 3 | J38: =IF(G38="","",2*I38+G38) | K38: Corewarden's Hearthstone | L38: Item | M38: 265100 | N38: inv_cosmicvoid_groundsate | P38: SAME | Q38: Corewarden's Hearthstone | R38: Same as Beast Mastery. | S38: VERIFIED | T38: Item 265100 | U38: icon
A39: Bar 4 | B39: 26 | C39: Item | D39: ALT-1 | F39: Cross char utility | H39: Item 140192 | I39: =IFERROR(INDEX('Key reach tiers'!$B$2:$B$48,MATCH(D39,'Key reach tiers'!$A$2:$A$48,0)),3) -> 3 | J39: =IF(G39="","",2*I39+G39) | K39: Dalaran Hearthstone | L39: Item | M39: 140192 | N39: inv_misc_rune_15 | P39: SAME | Q39: Dalaran Hearthstone | R39: Same as Beast Mastery. | S39: VERIFIED | T39: Dalaran Hearthstone | U39: icon
A40: Bar 4 | B40: 27 | C40: Item | D40: ALT-2 | F40: Cross char utility | H40: Name not resolved | I40: =IFERROR(INDEX('Key reach tiers'!$B$2:$B$48,MATCH(D40,'Key reach tiers'!$A$2:$A$48,0)),3) -> 3 | J40: =IF(G40="","",2*I40+G40) | K40: Personal Key to the Arcantina | L40: Item | M40: 253629 | N40: inv_12_-arcantina_key | P40: SAME | Q40: Personal Key to the Arcantina | R40: Same as Beast Mastery. | S40: VERIFIED | T40: Item 253629 | U40: icon
...

Sheet Hunter MM spells
A1: Rank (5 = most used) | B1: Spell | C1: Spell ID | D1: Category | E1: Tree | F1: Status | G1: Placed in slot(s) | H1: Note | I1: Icon file | J1: Wowhead link
A2: 5 | B2: Aimed Shot | C2: 19434 | D2: Attack/Heal | E2: spec | F2: VERIFIED | G2: 5 | H2: Cast on cooldown; every cast grants Precise Shots (Wowhead MM rotation). The AS macro stops it cancelling Rapid Fire. | I2: 8026692 | J2: https://www.wowhead.com/spell=19434
A3: 5 | B3: Arcane Shot | C3: 185358 | D3: Attack/Heal | E3: baseline | F3: VERIFIED | G3: 7 | H3: Single-target Precise Shots spender; the ArS macro avoids cancelling Rapid Fire. | I3: ability_impalingbolt | J3: https://www.wowhead.com/spell=185358
A4: 5 | B4: Black Arrow | C4: 466932 | D4: Attack/Heal | E4: hero:Dark Ranger | F4: VERIFIED | G4: not placed | H4: Precise Shots spender for Dark Ranger. Guide id 466932. | I4: inv_ability_darkrangerhunter_blackarrow | J4: https://www.wowhead.com/spell=466932
A5: 5 | B5: Rapid Fire | C5: 257044 | D5: Attack/Heal | E5: spec | F5: VERIFIED | G5: 2 | H5: Cast on cooldown; also grants Precise Shots. | I5: ability_hunter_efficiency | J5: https://www.wowhead.com/spell=257044
A6: 4 | B6: Explosive Shot | C6: 212431 | D6: Attack/Heal | E6: spec | F6: VERIFIED | G6: 4 | H6: On cooldown. | I6: ability_hunter_explosiveshot | J6: https://www.wowhead.com/spell=212431
A7: 4 | B7: Multi-Shot | C7: 257620 | D7: Attack/Heal | E7: baseline | F7: VERIFIED | G7: 3 | H7: 2+ target Precise Shots spender (Trick Shots). Guide id 257620. | I7: ability_upgrademoonglaive | J7: https://www.wowhead.com/spell=257620
A8: 4 | B8: Steady Shot | C8: 56641 | D8: Attack/Heal | E8: baseline | F8: VERIFIED | G8: 6 | H8: Filler; castable while moving, so 'always be casting'. | I8: ability_hunter_steadyshot | J8: https://www.wowhead.com/spell=56641
A9: 4 | B9: Trueshot | C9: 288613 | D9: Burst | E9: spec | F9: VERIFIED | G9: 65 | H9: Main cooldown; use on cooldown, keep the last use for 30 Bullseye stacks. | I9: ability_trueshot | J9: https://www.wowhead.com/spell=288613
A10: 4 | B10: Volley | C10: 260243 | D10: Burst | E10: spec | F10: VERIFIED | G10: 66 | H10: On cooldown. | I10: ability_hunter_rapidkilling | J10: https://www.wowhead.com/spell=260243
A11: 3 | B11: Aspect of the Cheetah | C11: 186257 | D11: Mobility | E11: baseline | F11: VERIFIED | G11: 49 | I11: ability_mount_jungletiger | J11: https://www.wowhead.com/spell=186257
A12: 3 | B12: Counter Shot | C12: 147362 | D12: Crowd control | E12: class | F12: VERIFIED | G12: 50, 51, 59 | I12: inv_ammo_arrow_03 | J12: https://www.wowhead.com/spell=147362
A13: 3 | B13: Disengage | C13: 781 | D13: Mobility | E13: baseline | F13: VERIFIED | G13: 52 | I13: ability_rogue_feint | J13: https://www.wowhead.com/spell=781
A14: 3 | B14: Kill Shot | C14: 53351 | D14: Attack/Heal | E14: spec | F14: VERIFIED | G14: 55 | H14: Precise Shots spender at execute. | I14: ability_hunter_assassinate2 | J14: https://www.wowhead.com/spell=53351
A15: 3 | B15: Misdirection | C15: 34477 | D15: Utility | E15: class | F15: VERIFIED | G15: 56 | I15: ability_hunter_misdirection | J15: https://www.wowhead.com/spell=34477
A16: 3 | B16: Moonlight Chakram | C16: 1264902 | D16: Burst | E16: hero:Sentinel | F16: VERIFIED | G16: 67 | H16: Cast with about 5 s of Trueshot left. | I16: inv_ability_hunter_deathchakram | J16: https://www.wowhead.com/spell=1264902
A17: 3 | B17: Wailing Arrow | C17: 392060 | D17: Burst | E17: hero:Dark Ranger | F17: VERIFIED | G17: not placed | H17: Single cast during Trueshot, Dark Ranger only. | I17: ability_theblackarrow | J17: https://www.wowhead.com/spell=392060
A18: 2 | B18: Aspect of the Turtle | C18: 186265 | D18: Defensive | E18: baseline | F18: VERIFIED | G18: 57 | I18: ability_hunter_pet_turtle | J18: https://www.wowhead.com/spell=186265
A19: 2 | B19: Exhilaration | C19: 109304 | D19: Defensive | E19: baseline | F19: VERIFIED | G19: 54 | I19: ability_hunter_onewithnature | J19: https://www.wowhead.com/spell=109304
A20: 2 | B20: Feign Death | C20: 5384 | D20: Utility | E20: baseline | F20: VERIFIED | G20: 63 | I20: ability_rogue_feigndeath | J20: https://www.wowhead.com/spell=5384
A21: 2 | B21: Freezing Trap | C21: 187650 | D21: Crowd control | E21: baseline | F21: VERIFIED | G21: 64 | I21: spell_frost_chainsofice | J21: https://www.wowhead.com/spell=187650
A22: 2 | B22: Growl | C22: 2649 | D22: Utility | E22: pet | F22: VERIFIED | G22: 9 | I22: ability_physical_taunt | J22: https://www.wowhead.com/spell=2649
A23: 2 | B23: Hunter's Mark | C23: 257284 | D23: Attack/Heal | E23: baseline | F23: VERIFIED | G23: 8 | I23: ability_hunter_markedfordeath | J23: https://www.wowhead.com/spell=257284
A24: 2 | B24: Intimidation | C24: 474421 | D24: Crowd control | E24: class | F24: VERIFIED | G24: 60, 62 | H24: MM class-tree id 474421 (BM and SV show 19577); the Kick2/AutoKick2 macros cast it by name. | I24: artifactability_survivalhunter_eaglesbite | J24: https://www.wowhead.com/spell=474421
A25: 2 | B25: Mend Pet | C25: 136 | D25: Attack/Heal | E25: baseline | F25: VERIFIED | G25: 1 | I25: ability_hunter_mendpet | J25: https://www.wowhead.com/spell=136
A26: 2 | B26: Revive Pet | C26: 982 | D26: Utility | E26: baseline | F26: VERIFIED | G26: 68 | I26: ability_hunter_beastsoothe | J26: https://www.wowhead.com/spell=982
A27: 2 | B27: Survival of the Fittest | C27: 264735 | D27: Defensive | E27: class | F27: VERIFIED | G27: 53 | I27: spell_nature_spiritarmor | J27: https://www.wowhead.com/spell=264735
A28: 1 | B28: Beast Lore | C28: 1462 | D28: Utility | E28: baseline | F28: VERIFIED | G28: 69 | I28: ability_physical_taunt | J28: https://www.wowhead.com/spell=1462
A29: 1 | B29: Binding Shot | C29: 109248 | D29: Crowd control | E29: class | F29: VERIFIED | G29: not placed | I29: spell_shaman_bindelemental | J29: https://www.wowhead.com/spell=109248
A30: 1 | B30: Call Pet 1 | C30: 883 | D30: Utility | E30: baseline | F30: VERIFIED | G30: not placed | I30: ability_hunter_beastcall | J30: https://www.wowhead.com/spell=883
A31: 1 | B31: Camouflage | C31: 199483 | D31: Utility | E31: class | F31: VERIFIED | G31: not placed | I31: ability_hunter_camouflage | J31: https://www.wowhead.com/spell=199483
A32: 1 | B32: Concussive Shot | C32: 5116 | D32: Crowd control | E32: class | F32: VERIFIED | G32: not placed | I32: spell_frost_stun | J32: https://www.wowhead.com/spell=5116
A33: 1 | B33: Dismiss Pet | C33: 2641 | D33: Utility | E33: baseline | F33: VERIFIED | G33: not placed | I33: spell_nature_spiritwolf | J33: https://www.wowhead.com/spell=2641
A34: 1 | B34: Flare | C34: 1543 | D34: Utility | E34: baseline | F34: VERIFIED | G34: not placed | I34: spell_fire_flare | J34: https://www.wowhead.com/spell=1543
A35: 1 | B35: Primal Rage | C35: 264667 | D35: Burst | E35: pet | F35: VERIFIED | G35: not placed | I35: spell_shadow_unholyfrenzy | J35: https://www.wowhead.com/spell=264667
A36: 1 | B36: Roar of Sacrifice | C36: 53480 | D36: Defensive | E36: class choice | F36: VERIFIED | G36: not placed | I36: ability_hunter_fervor | J36: https://www.wowhead.com/spell=53480
... A40: 1 | B40: Tranquilizing Shot | C40: 19801 | D40: Utility | E40: class | F40: VERIFIED | G40: 61 | I40: spell_nature_drowsy | J40: https://www.wowhead.com/spell=19801
A43: Rotation priority (Sentinel, single target) from https://www.wowhead.com/guide/classes/hunter/marksmanship/rotation-cooldowns-pve-dps
A44: 1. Trueshot on cooldown (keep the final use for 30 Bullseye stacks)
A45: 2. Moonlight Chakram with about 5 s of Trueshot left
...

Sheet Hunter - Survival
A1: Bar | B1: Slot | C1: Type | D1: Key 1 | E1: Key 2 | F1: keys reserved for | G1: Importance of slots | H1: Input notes (xlsx Details) | I1: Key reach tier | J1: Priority score | K1: Recommended action | L1: Placed as | M1: ID / macro id | N1: Icon file | O1: Spell rank (1-5) | P1: vs Beast Mastery | Q1: Beast Mastery has | R1: Reason | S1: Status | T1: xlsx spell (unreliable) | U1: Icon link
A2: Bar 1 | B2: 1 | C2: Spell | D2: 1 | F2: Attack/Heal | G2: 2 | H2: Beast Cleave | I2: =IFERROR(INDEX('Key reach tiers'!$B$2:$B$48,MATCH(D2,'Key reach tiers'!$A$2:$A$48,0)),3) -> 1 | J2: =IF(G2="","",2*I2+G2) -> 4 | K2: Mend Pet | L2: Spell | M2: 136 | N2: ability_hunter_mendpet | O2: 2 | P2: SAME | Q2: Mend Pet | R2: Same as Beast Mastery. | S2: VERIFIED | T2: Multi-Shot | U2: icon
A3: Bar 1 | B3: 2 | C3: Spell | D3: 2 | F3: Attack/Heal | G3: 1 | I3: =IFERROR(INDEX('Key reach tiers'!$B$2:$B$48,MATCH(D3,'Key reach tiers'!$A$2:$A$48,0)),3) -> 1 | J3: =IF(G3="","",2*I3+G3) -> 3 | K3: Wildfire Bomb | L3: Spell | M3: 259495 | N3: inv_wildfirebomb | O3: 5 | P3: DIFFERENT | Q3: Cobra Shot macro 'Cobra' | R3: Rank 5 cooldown ability on the thumb button, where BM keeps Barbed Shot. | S3: VERIFIED | T3: Kill Command | U3: icon
A4: Bar 1 | B4: 3 | C4: Spell | D4: 3 | F4: Attack/Heal | G4: 1 | I4: =IFERROR(INDEX('Key reach tiers'!$B$2:$B$48,MATCH(D4,'Key reach tiers'!$A$2:$A$48,0)),3) -> 1 | J4: =IF(G4="","",2*I4+G4) -> 3 | K4: Raptor Swipe | L4: Spell | M4: 1259003 | N4: inv12_apextalent_hunter_raptorswipe | O4: 4 | P4: DIFFERENT | Q4: Wild Thrash macro 'Wild' | R4: Rank 4 apex ability, on the key BM uses for Wild Thrash. | S4: VERIFIED | T4: Barbed Shot | U4: icon
A5: Bar 1 | B5: 4 | C5: Spell | D5: 4 | F5: Attack/Heal | G5: 2 | H5: From your BM bar | I5: =IFERROR(INDEX('Key reach tiers'!$B$2:$B$48,MATCH(D5,'Key reach tiers'!$A$2:$A$48,0)),3) -> 1 | J5: =IF(G5="","",2*I5+G5) -> 4 | K5: Boomstick | L5: Spell | M5: 1261193 | N5: inv_musket_04 | O5: 4 | P5: DIFFERENT | Q5: Bestial Wrath macro 'BW' | R5: Rank 4, third in the Wowhead priority. | S5: VERIFIED | T5: Wild Thrash | U5: icon
A6: Bar 1 | B6: 5 | C6: Spell | D6: R | F6: Attack/Heal | G6: 1 | I6: =IFERROR(INDEX('Key reach tiers'!$B$2:$B$48,MATCH(D6,'Key reach tiers'!$A$2:$A$48,0)),3) -> 1 | J6: =IF(G6="","",2*I6+G6) -> 3 | K6: Kill Command macro 'KC' | L6: Macro | M6: 17 | N6: ability_hunter_killcommand | O6: 5 | P6: SAME | Q6: Kill Command macro 'KC' | R6: Same as Beast Mastery. | S6: VERIFIED | T6: Cobra Shot | U6: icon
A7: Bar 1 | B7: 6 | C7: Spell | D7: F | F7: Attack/Heal | G7: 2 | H7: AoE opener | I7: =IFERROR(INDEX('Key reach tiers'!$B$2:$B$48,MATCH(D7,'Key reach tiers'!$A$2:$A$48,0)),3) -> 1 | J7: =IF(G7="","",2*I7+G7) -> 4 | K7: Raptor Strike macro 'Raptor' | L7: Macro | M7: 38 | N7: ability_hunter_raptorstrike | O7: 5 | P7: DIFFERENT | Q7: Cobra Shot macro 'Cobra' | R7: Second copy of the filler on F with the pet-attack lines, mirroring Cobra Shot in BM. New macro. | S7: VERIFIED | T7: Dire Beast | U7: icon
A8: Bar 1 | B8: 7 | C8: Spell | D8: BUTTON4 | F8: Attack/Heal | G8: 1 | H8: Dark Ranger | I8: =IFERROR(INDEX('Key reach tiers'!$B$2:$B$48,MATCH(D8,'Key reach tiers'!$A$2:$A$48,0)),3) -> 1 | J8: =IF(G8="","",2*I8+G8) -> 3 | K8: Raptor Strike | L8: Spell | M8: 186270 | N8: ability_hunter_raptorstrike | O8: 5 | P8: DIFFERENT | Q8: Barbed Shot macro 'Barbed' | R8: Rank 5 core spender, on the first importance-1 key (BM's Cobra Shot slot). | S8: VERIFIED | T8: Black Arrow | U8: icon
A9: Bar 1 | B9: 8 | C9: Spell | D9: SHIFT-BUTTON4 | F9: Attack/Heal | G9: 2 | I9: =IFERROR(INDEX('Key reach tiers'!$B$2:$B$48,MATCH(D9,'Key reach tiers'!$A$2:$A$48,0)),3) -> 2 | J9: =IF(G9="","",2*I9+G9) -> 6 | K9: Hunter's Mark | L9: Spell | M9: 257284 | N9: ability_hunter_markedfordeath | O9: 3 | P9: SAME | Q9: Hunter's Mark | R9: Same as Beast Mastery. | S9: VERIFIED | T9: Hunter's Mark | U9: icon
A10: Bar 1 | B10: 9 | C10: Spell | D10: V | F10: Utility | G10: 3 | I10: =IFERROR(INDEX('Key reach tiers'!$B$2:$B$48,MATCH(D10,'Key reach tiers'!$A$2:$A$48,0)),3) -> 2 | J10: =IF(G10="","",2*I10+G10) -> 7 | K10: Growl macro 'Growl' | L10: Macro | M10: 16 | N10: ability_physical_taunt | O10: 2 | P10: SAME | Q10: Growl macro 'Growl' | R10: Same as Beast Mastery. | S10: VERIFIED | T10: Tranquilizing Shot | U10: icon
A11: Bar 1 | B11: 10 | C11: Spell | D11: SHIFT-V | F11: Utility | G11: 3 | I11: =IFERROR(INDEX('Key reach tiers'!$B$2:$B$48,MATCH(D11,'Key reach tiers'!$A$2:$A$48,0)),3) -> 3 | J11: =IF(G11="","",2*I11+G11) -> 9 | K11: Tame Beast macro 'tame' | L11: Macro | M11: 27 | N11: ability_hunter_beasttaming | O11: 1 | P11: SAME | Q11: Tame Beast macro 'tame' | R11: Same as Beast Mastery. | S11: VERIFIED | T11: Misdirection | U11: icon
